Workbook
Name Cost_Lever: [1]Segmentation2!#REF!
Name Cost_Lever: [1]Segmentation2!#REF!
Name Cost_Lever: [1]Segmentation2!#REF!
Name Cost_Lever: [1]Segmentation2!#REF!
Name Cost_Lever: [1]Segmentation2!#REF!
Name Cost_Lever: #REF!
Name Cost_Lever: #REF!
Name Cost_Lever: [1]Segmentation2!#REF!
Name Cost_Lever: [1]Segmentation2!#REF!
Name Cost_Lever: [1]Segmentation2!#REF!
Name Cost_Lever: #REF!
Name Cost_Lever: #REF!
Name Cost_Lever: [1]Segmentation2!#REF!
Name Cost_Lever: #REF!
Name Cost_Lever: [1]Segmentation2!#REF!
Name Cost_Lever: [1]Segmentation2!#REF!
Name Cost_Lever: #REF!
Name Cost_Lever: [1]Segmentation2!#REF!
Name Cost_Lever: #REF!
Name Cost_Lever: #REF!
Name Cost_Lever: #REF!
Name Cost_Lever: [1]Segmentation2!#REF!
Name Cost_Lever: #REF!
Name Cost_Lever: #REF!
Name Cost_Lever: [1]Segmentation2!#REF!
Name Cost_Lever: #REF!
Name Cost_Lever: #REF!
Name Cost_Lever: [1]Segmentation2!#REF!
Name Cost_Lever: [1]Segmentation2!#REF!
Name DOA: #REF!
Name DOA: #REF!
Name DOA: #REF!
Name DOA: #REF!
Name DOA: #REF!
Name DOA: #REF!
Name DOA: #REF!
Name DOA: #REF!
Name DOA: #REF!
Name DOA: #REF!
Name DOA: #REF!
Name DOA: #REF!
Name DOA: #REF!
Name DOA: #REF!
Name DOA: #REF!
Name DOA: [1]references!$W$2:$W$6
Name Niv0: #REF!
Name Niv0: #REF!
Name Niv0: #REF!
Name Niv0: #REF!
Name Niv0: #REF!
Name Niv0: #REF!
Name Niv0: #REF!
Name Niv0: #REF!
Name Niv0: #REF!
Name Niv0: #REF!
Name Niv0: #REF!
Name Niv0: #REF!
Name Niv0: #REF!
Name Niv0: #REF!
Name Niv0: #REF!

Sheet End dates
A3: Étiquettes de lignes | B3: End Dates of lease
A4: 1. Europe
A5: Allianz Global Benefits
A6: Germany
A7: Seidlstrasse 24-24a
A8: Munich | B8: 48913
A9: Uhlandstrasse 2
A10: Stuttgart | B10: 0
A11: BU Austria
A12: Austria
A13: Linzer Strasse 225
A14: Vienna | B14: 47635
A15: Bulgaria
A16: 16 Srebarna Str.
A17: Sofia | B17: 48029
A18: Hungary
A19: Könyves Kalman krt. 48-52
A20: Budapest | B20: 46477
A21: Romania
A22: Globalworth Campus, C Building · 2-4, Ing. George Constantinescu 11th floor, 2nd District
A23: Bucharest | B23: 47483
A24: BU Czech Republic
A25: Czech Republic
A26: Čajakova 18
A27: Bratislava | B27: 0
A28: Jankovcova 1596/14B
A29: Prague | B29: 46599
A30: BU France
A31: France
A32: 151 Boulevard Victor Hugo
A33: Saint Ouen | B33: 46356
A34: 7 rue Dora Maar
A35: Saint Ouen | B35: 49064
A36: 79-81 Rue Pierre Semard
A37: Chatillon | B37: 46295
A38: 85 Quai de Beauvais
A39: Armentières | B39: 47026
A40: Chemin aux bœuf & les Hunaudières
A41: Le Mans | B41: 47177
A42: BU Germany (AHS)
...

Sheet DataCube
A2: New Region | B2: BU | C2: Country | D2: City | E2: Postal code | F2: Street Address | G2: Rental/Owned/ Sublease | H2: Location unique ID | I2: Located at AZ entity (Yes/No) | J2: Unit description | K2: Size (m²or Ft) | L2: Currency code | M2: Rental Cost/m² | N2: Indexation | O2: Rental Cost | P2: Facility Costs | Q2: # of Employees | R2: # of workstation | S2: Ratio workstation/ employee | T2: sqm/workstation | U2: sqm/employee | V2: Lease Start Date | W2: Lease End Date | X2: Next Break Date | Y2: Sublease Contract in Place (Yes/No) | Z2: Renewable energy? Yes/No | AA2: Sustainability Certification | AB2: CRE & FM Function | AC2: Last update | AD2: Lease Notes/ Comments
A3: 2. Asia | B3: =Thailand!$F$4 -> 0 | C3: =Thailand!$F$17 -> 0 | D3: =Thailand!$F$15 -> 0 | E3: =Thailand!$F$16 -> 0 | F3: =Thailand!$F$14 -> 0 | G3: =Thailand!$F$18 -> 0 | H3: =Thailand!$F$11 -> 0 | I3: =Thailand!$F$19 -> 0 | J3: =Thailand!$F$13 -> 0 | K3: =Thailand!$F$24 -> 0 | L3: =Thailand!$F$26 -> 0 | M3: =Thailand!$F$28 -> 0 | N3: =Thailand!$F$29 -> 0 | O3: =Thailand!$F$27 -> 0 | P3: =Thailand!$F$30 -> 0 | Q3: =Thailand!$F$46 -> 0 | R3: =Thailand!$F$50 -> 0 | S3: =R3/Q3 -> #DIV/0! | T3: =K3/R3 -> #DIV/0! | U3: =K3/Q3 -> #DIV/0! | V3: =Thailand!$F$33 -> 0 | W3: =Thailand!$F$40 -> 0 | X3: =Thailand!$F$34 -> 0 | Y3: =Thailand!$F$42 -> 0 | Z3: =Thailand!$F$43 -> 0 | AA3: =Thailand!$F$44 -> 0 | AB3: =Thailand!$F$9 -> 0 | AC3: =Thailand!$D$2 -> 46058
A4: 2. Asia | B4: =Australia!$D$4 -> BU Australia | C4: =Australia!$D$17 -> Australia | D4: =Australia!$D$15 -> Brisbane | E4: =Australia!$D$16 -> 4000 | F4: =Australia!$D$14 -> 310 Ann St | G4: =Australia!$D$18 -> Rental | H4: =Australia!$D$11 -> AU01 | I4: =Australia!$D$19 -> No | J4: =Australia!$D$13 -> Levels 12-18 | K4: =Australia!$D$24 -> 7993 | L4: =Australia!$D$26 -> AUD | M4: =Australia!$D$28 -> 805.4 | N4: =Australia!$D$29 -> 3.75% per annum on anniversary date | P4: =Australia!$D$30 -> 731245 | Q4: =Australia!$D$46 -> 619 | R4: =Australia!$D$50 -> 386 | S4: =R4/Q4 -> 0.62358643 | T4: =K4/R4 -> 20.707254 | U4: =K4/Q4 -> 12.912763 | V4: =Australia!$D$33 -> 43497 | W4: =Australia!$D$40 -> 47361 | X4: =Australia!$D$34 -> 47361 | Y4: =Australia!$D$42 -> Yes | Z4: =Australia!$D$43 -> No | AA4: =Australia!$D$44 -> Yes- NABERS 5.5 star energy rating & working on NABERS rating for waste | AB4: =Australia!$D$9 -> sbishop@allianz-assistance.com.au | AC4: =Australia!$D$2 -> 0
A5: 2. Asia | B5: =Australia!$D$4 -> BU Australia | C5: =Australia!$E$17 -> Australia | D5: =Australia!$E$15 -> Brisbane | E5: =Australia!$E$16 -> 4000 | F5: =Australia!$E$14 -> 310 Ann St | G5: =Australia!$E$18 -> Rental | H5: =Australia!$E$11 -> AU01 | I5: =Australia!$E$19 -> No | J5: =Australia!$E$13 -> Levels 12-14 | K5: =Australia!$E$24 -> 3441 | L5: =Australia!$E$26 -> AUD | M5: =Australia!$E$28 -> $565/ sqm Less incentive of $88.25 / sqm Net rent $476.75 | N5: =Australia!$E$29 -> 3.75% per annum on anniversary date | O5: =Australia!$E$27 -> 0 | P5: =Australia!$E$30 -> Base building charges recovered from sub tenant of $98,000 per yr plus a proportion of some of the direct vendor costs that relate to the maintenance of the tenancy | S5: =R5/Q5 -> #DIV/0! | T5: =K5/R5 -> #DIV/0! | U5: =K5/Q5 -> #DIV/0! | V5: =Australia!E33 -> 44743 | W5: =Australia!E40 -> 46568 | X5: =Australia!E34 -> 46568 | Y5: =Australia!$E$42 -> subleaser | AC5: =Australia!$D$2 -> 0
A6: 1. Europe | B6: =Austria!$D$4 -> BU Austria | C6: =Austria!$D$17 -> Austria | D6: =Austria!$D$15 -> Vienna | E6: =Austria!$D$16 -> 1140 | F6: =Austria!$D$14 -> Linzer Strasse 225 | G6: =Austria!$D$18 -> Rental | H6: =Austria!$D$11 -> AT01 | I6: =Austria!$D$19 -> Yes | J6: =Austria!$D$13 -> 3rd floor | K6: =Austria!$D$24 -> 890 | L6: =Austria!$D$26 -> EUR | M6: =Austria!$D$28 -> 16,80/m² | N6: =Austria!$D$29 -> CPI | O6: =Austria!$D$27 -> 0 | P6: =Austria!$D$30 -> 173.4 | Q6: =Austria!$D$46 -> 220 | R6: =Austria!$D$50 -> 87 | S6: =R6/Q6 -> 0.39545455 | T6: =K6/R6 -> 10.229885 | U6: =K6/Q6 -> 4.0454545 | V6: =Austria!$D$33 -> 45261 | W6: =Austria!$D$40 -> 47635 | X6: =Austria!$D$34 -> 45444 | Y6: =Austria!$D$42 -> No | Z6: =Austria!$D$43 -> Yes | AA6: =Austria!$D$44 -> No | AB6: =Austria!$D$9 -> 0 | AC6: =Austria!$D$2 -> 45919
A7: 4. H&L | B7: =Belgium!$D$4 -> International Health | C7: =Belgium!$D$17 -> Belgium | D7: =Belgium!$D$15 -> Brussels | E7: =Belgium!$D$16 -> 1000 | F7: =Belgium!$D$14 -> Allianz Tower Koning Boulevard du Roi Albert II, 32 (Albert II Laan) | G7: =Belgium!$D$18 -> Rental | H7: =Belgium!$D$11 -> BE01 | I7: =Belgium!$D$19 -> Yes | J7: =Belgium!$D$13 -> 4th floor & 50% of the 5th floor | K7: =Belgium!$D$24 -> 1658 | L7: =Belgium!$D$26 -> EUR | M7: =Belgium!$D$28 -> 373 | N7: =Belgium!$D$29 -> app. 3% | O7: =Belgium!$D$27 -> 618434 | P7: =Belgium!$D$30 -> 259 | Q7: =Belgium!$D$46 -> 222 | R7: =Belgium!$D$50 -> 142 | S7: =R7/Q7 -> 0.63963964 | T7: =K7/R7 -> 11.676056 | U7: =K7/Q7 -> 7.4684685 | V7: =Belgium!$D$33 -> 43922 | W7: =Belgium!$D$40 -> 47208 | X7: =Belgium!$D$34 -> 47208 | Y7: =Belgium!$D$42 -> No | Z7: =Belgium!$D$43 -> Yes | AA7: =Belgium!$D$44 -> Unknown | AB7: =Belgium!$D$9 -> 0 | AC7: =Belgium!$D$2 -> 46070
A8: 3. Americas | B8: =Brazil!$D$4 -> BU Brazil | C8: =Brazil!$D$17 -> Brazil | D8: =Brazil!$D$15 -> São Bernardo do Campo | E8: =Brazil!$D$16 -> 09751-020 | F8: =Brazil!$D$14 -> Rua José Versolato, 101 | G8: =Brazil!$D$18 -> Rental | H8: =Brazil!$D$11 -> BR01 | I8: =Brazil!$D$19 -> No | J8: =Brazil!$D$13 -> 5th, 6th, 8th and 9th floor | K8: =Brazil!$D$24 -> 3256 | L8: =Brazil!$D$26 -> BRL | M8: =Brazil!$D$28 -> 577 | N8: =Brazil!$D$29 -> 0.09 | O8: =Brazil!$D$27 -> 0 | P8: =Brazil!$D$30 -> 114 | Q8: =Brazil!$D$46 -> 1300 | R8: =Brazil!$D$50 -> 752 | S8: =R8/Q8 -> 0.57846154 | T8: =K8/R8 -> 4.3297872 | U8: =K8/Q8 -> 2.5046154 | V8: =Brazil!$D$33 -> 42614 | W8: =Brazil!$D$40 -> 46234 | X8: =Brazil!$D$34 -> 42582 | Y8: =Brazil!$D$42 -> N/A | Z8: =Brazil!$D$43 -> No | AA8: =Brazil!$D$44 -> No | AB8: =Brazil!$D$9 -> 0 | AC8: =Brazil!$D$2 -> 45961
A9: 3. Americas | B9: =Brazil!$D$4 -> BU Brazil | C9: =Brazil!$E$17 -> Brazil | D9: =Brazil!$E$15 -> São Bernardo do Campo | E9: =Brazil!$E$16 -> 09751-020 | F9: =Brazil!$E$14 -> Rua José Versolato, 101 (2nd contract) | G9: =Brazil!$E$18 -> Rental | H9: =Brazil!$E$11 -> BR01 | I9: =Brazil!$E$19 -> No | J9: =Brazil!$E$13 -> 50% of the 6th floor | K9: =Brazil!$E$24 -> 711 | L9: =Brazil!$E$26 -> BRL | M9: =Brazil!$E$28 -> 600 | N9: =Brazil!$E$29 -> 0.09 | O9: =Brazil!$E$27 -> 0 | P9: =Brazil!$E$30 -> 21 | Q9: =Brazil!$E$46 -> 200 | R9: =Brazil!$E$50 -> 154 | S9: =R9/Q9 -> 0.77 | T9: =K9/R9 -> 4.6168831 | U9: =K9/Q9 -> 3.555 | V9: =Brazil!$E$33 -> 44927 | W9: =Brazil!$E$40 -> 46387 | X9: =Brazil!$E$34 -> 46387 | Y9: =Brazil!$E$42 -> N/A | Z9: =Brazil!$E$43 -> No | AA9: =Brazil!$E$44 -> No | AB9: =Brazil!$E$9 -> 0 | AC9: =Brazil!$E$2 -> 0
A10: 1. Europe | B10: =Bulgaria!$D$4 -> BU Austria | C10: =Bulgaria!$D$17 -> Bulgaria | D10: =Bulgaria!$D$15 -> Sofia | E10: =Bulgaria!$D$16 -> 1407 | F10: =Bulgaria!$D$14 -> 16 Srebarna Str. | G10: =Bulgaria!$D$18 -> Rental | H10: =Bulgaria!$D$11 -> BU01 | I10: =Bulgaria!$D$19 -> No | J10: =Bulgaria!$D$13 -> part of a floor | K10: =Bulgaria!$D$24 -> 45.77 | L10: =Bulgaria!$D$26 -> EUR | M10: =Bulgaria!$D$28 -> 156 | N10: =Bulgaria!$D$29 -> CPI | O10: =Bulgaria!$D$27 -> 0 | P10: =Bulgaria!$D$30 -> 53.6 | Q10: =Bulgaria!$D$46 -> 6 | R10: =Bulgaria!$D$50 -> 6 | S10: =R10/Q10 -> 1 | T10: =K10/R10 -> 7.6283333 | U10: =K10/Q10 -> 7.6283333 | V10: =Bulgaria!$D$33 -> 44378 | W10: =Bulgaria!$D$40 -> 48029 | X10: =Bulgaria!$D$34 -> 48029 | Y10: =Bulgaria!$D$42 -> No | Z10: =Bulgaria!$D$43 -> No | AA10: =Bulgaria!$D$44 -> No | AB10: =Bulgaria!$D$9 -> 0 | AC10: =Bulgaria!$D$2 -> 45919
A11: 3. Americas | B11: =Canada!$D$4 -> BU Canada | C11: =Canada!$D$17 -> Canada | D11: =Canada!$D$15 -> Cambridge | E11: =Canada!$D$16 -> N3C 4N6 | F11: =Canada!$D$14 -> 700 Jamieson Pkwy. Cambridge | G11: =Canada!$E$18 -> Sublease | H11: =Canada!$E$11 -> CA01 | I11: =Canada!$E$19 -> 0 | J11: =Canada!$E$13 -> 0 | K11: =Canada!$E$24 -> 3376.4666 | L11: =Canada!$E$26 -> CAD | M11: =Canada!$E$28 -> 17 | N11: =Canada!$E$29 -> Year 1-5 - $17.00 Year 6-10 - $18.00 Year 11-14 - $19.00 | O11: =Canada!$E$27 -> 0 | P11: =Canada!$E$30 -> 0 | Q11: =Canada!$E$46 -> 0 | R11: =Canada!$E$50 -> 0 | S11: =R11/Q11 -> #DIV/0! | T11: =K11/R11 -> #DIV/0! | U11: =K11/Q11 -> #DIV/0! | V11: =Canada!$E$33 -> 44075 | W11: =Canada!$E$40 -> 49033 | X11: =Canada!$E$34 -> N/A | Y11: =Canada!$E$42 -> Sublet: Superior Propane Aug 01/20-Mar 30/34 | Z11: =Canada!$E$43 -> 0 | AA11: =Canada!$E$44 -> 0 | AB11: =Canada!$E$9 -> 0 | AC11: =Canada!$E$2 -> 0
A12: 3. Americas | B12: =Canada!$D$4 -> BU Canada | C12: =Canada!$D$17 -> Canada | D12: =Canada!$D$15 -> Cambridge | E12: =Canada!$D$16 -> N3C 4N6 | F12: =Canada!$D$14 -> 700 Jamieson Pkwy. Cambridge | G12: =Canada!$F$18 -> Sublease | H12: =Canada!$F$11 -> CA01 | I12: =Canada!$F$19 -> 0 | J12: =Canada!$F$13 -> 0 | K12: =Canada!$F$24 -> 2319.3234 | L12: =Canada!$F$26 -> CAD | M12: =Canada!$F$28 -> 18.5 | N12: =Canada!$F$29 -> Year 1-4 - $18.50 Year 5-8- $19.50 Year 9-11 - $20.50 | O12: =Canada!$F$27 -> 0 | P12: =Canada!$F$30 -> 0 | Q12: =Canada!$F$46 -> 0 | R12: =Canada!$F$50 -> 0 | S12: =R12/Q12 -> #DIV/0! | T12: =K12/R12 -> #DIV/0! | U12: =K12/Q12 -> #DIV/0! | V12: =Canada!$F$33 -> 45078 | W12: =Canada!$F$40 -> 49033 | X12: =Canada!$F$34 -> N/A | Y12: =Canada!$F$42 -> 2nd Sublet: Reeds Heritage Homes(no details at this time) | Z12: =Canada!$F$43 -> 0 | AA12: =Canada!$F$44 -> 0 | AB12: =Canada!$F$9 -> 0 | AC12: =Canada!$F$2 -> 0
A13: 3. Americas | B13: =Canada!$D$4 -> BU Canada | C13: =Canada!$D$17 -> Canada | D13: =Canada!$D$15 -> Cambridge | E13: =Canada!$D$16 -> N3C 4N6 | F13: =Canada!$D$14 -> 700 Jamieson Pkwy. Cambridge | G13: =Canada!$D$18 -> Rental | H13: =Canada!$D$11 -> CA01 | I13: =Canada!$D$19 -> No | J13: =Canada!$D$13 -> Single story unattached office dwelling | K13: =Canada!$D$24 -> 10334.716 | L13: =Canada!$D$26 -> CAD | M13: =Canada!$D$28 -> 17.5 | N13: =Canada!$D$29 -> Year 1-5 - $17.50 Year 6-10 - $19.35 Year 11-15- $21.35 | O13: =Canada!$D$27 -> 0 | P13: =Canada!$D$30 -> 20.559078 | Q13: =Canada!$D$46 -> 668 | R13: =Canada!$D$50 -> 420 | S13: =R13/Q13 -> 0.62874251 | T13: =K13/R13 -> 24.606466 | U13: =K13/Q13 -> 15.471131 | V13: =Canada!$D$33 -> 43459 | W13: =Canada!$D$40 -> 49058 | X13: =Canada!$D$34 -> 49302 | Y13: =Canada!$D$42 -> Yes | Z13: =Canada!$D$43 -> Yes | AA13: =Canada!$D$44 -> LEED Silver | AB13: =Canada!$D$9 -> 0 | AC13: =Canada!$D$2 -> 45961
A14: 2. Asia | B14: =China!$D$4 -> BU China | C14: =China!$D$17 -> China | D14: =China!$D$15 -> Beijing | E14: =China!$D$16 -> 100123 | F14: =China!$D$14 -> Huitong Office Park, No.1 Yaojiayuan South Road, Chaoyang | G14: =China!$D$18 -> Rental | H14: =China!$D$11 -> CN01 | I14: =China!$D$19 -> No | J14: =China!$D$13 -> A Zone, Building 7# Floor 3-5 | K14: =China!$D$24 -> 2845 | L14: =China!$D$26 -> CNY | M14: =China!$D$28 -> 1766.6 | N14: =China!$D$29 -> 0 | O14: =China!$D$27 -> 0 | P14: =China!$D$30 -> 837.86 | Q14: =China!$D$46 -> 319 | R14: =China!$D$50 -> 303 | S14: =R14/Q14 -> 0.94984326 | T14: =K14/R14 -> 9.3894389 | U14: =K14/Q14 -> 8.9184953 | V14: =China!$D$33 -> 45301 | W14: =China!$D$40 -> 46396 | X14: =China!$D$34 -> 46031 | Y14: =China!$D$42 -> - | Z14: =China!$D$43 -> N | AA14: =China!$D$44 -> No | AB14: =China!$D$9 -> 0 | AC14: =China!$D$2 -> 0
A15: 2. Asia | B15: =China!$D$4 -> BU China | C15: =China!$D$17 -> China | D15: =China!$E$15 -> Chengdu | E15: =China!$E$16 -> 610041 | F15: =China!$E$14 -> E zone, Tianfu Software Park, Gaoxin District, Chengdu | G15: =China!$E$18 -> Rental | H15: =China!$E$11 -> CN02 | I15: =China!$E$19 -> No | J15: =China!$E$13 -> 9F, Tower E2 | K15: =China!$E$24 -> 2197 | L15: =China!$E$26 -> CNY | M15: =China!$E$28 -> 840 | N15: =China!$E$29 -> 0 | O15: =China!$E$27 -> 0 | P15: =China!$E$30 -> 624.35321 | Q15: =China!$E$46 -> 256 | R15: =China!$E$50 -> 398 | S15: =R15/Q15 -> 1.5546875 | T15: =K15/R15 -> 5.5201005 | U15: =K15/Q15 -> 8.5820312 | V15: =China!$E$33 -> 45246 | W15: =China!$E$40 -> 46934 | X15: =China!$E$34 -> 46022 | Y15: =China!$E$42 -> - | Z15: =China!$E$43 -> N | AA15: =China!$E$44 -> No | AB15: =China!$E$9 -> 0 | AC15: =China!$E$2 -> 0
A16: 2. Asia | B16: =China!$D$4 -> BU China | C16: =China!$F$17 -> China | D16: =China!$F$15 -> Shanghai | E16: =China!$F$16 -> 200120 | F16: =China!$F$14 -> Shanghai Tower, No.501 Yincheng Zhong Road, Pudong District | G16: =China!$F$18 -> Rental | H16: =China!$F$11 -> CN03 | I16: =China!$F$19 -> No | J16: =China!$F$13 -> Unit 1401 | K16: =China!$F$24 -> 550.16 | L16: =China!$F$26 -> CNY | M16: =China!$F$28 -> 3650.04 | N16: =China!$F$29 -> 0 | O16: =China!$F$27 -> 0 | P16: =China!$F$30 -> 1231.5327 | Q16: =China!$F$46 -> 37 | R16: =China!$F$50 -> 52 | S16: =R16/Q16 -> 1.4054054 | T16: =K16/R16 -> 10.58 | U16: =K16/Q16 -> 14.869189 | V16: =China!$F$33 -> 42975 | W16: =China!$F$40 -> 46644 | X16: =China!$F$34 -> 45940 | Y16: =China!$F$42 -> - | Z16: =China!$F$43 -> N | AA16: =China!$F$44 -> No | AB16: =China!$F$9 -> 0 | AC16: =China!$F$2 -> 0
A17: 3. Americas | B17: =Colombia!$D$4 -> BU Colombia | C17: =Colombia!$D$17 -> Colombia | D17: =Colombia!$D$15 -> Bogota | E17: =Colombia!$D$16 -> 110110 | F17: =Colombia!$D$14 -> 72b Street # 6-44 | G17: =Colombia!$D$18 -> Rental | H17: =Colombia!$D$11 -> CO01 | I17: =Colombia!$D$19 -> Yes | J17: =Colombia!$D$13 -> Location from floor 2 to floor 4 | K17: =Colombia!$D$24 -> 863.93 | L17: =Colombia!$D$26 -> COP | M17: =Colombia!$D$28 -> 475787.52 | N17: =Colombia!$D$29 -> IPC (CPI) | O17: =Colombia!$D$27 -> 0 | P17: =Colombia!$D$30 -> 266162.49 | Q17: =Colombia!$D$46 -> 136 | R17: =Colombia!$D$50 -> 116 | S17: =R17/Q17 -> 0.85294118 | T17: =K17/R17 -> 7.4476724 | U17: =K17/Q17 -> 6.3524265 | V17: =Colombia!$D$33 -> 44652 | W17: =Colombia!$D$40 -> 46477 | X17: =Colombia!$D$34 -> 46112 | Y17: =Colombia!$D$42 -> No | Z17: =Colombia!$D$43 -> No | AA17: =Colombia!$D$44 -> No | AB17: =Colombia!$D$9 -> 0 | AC17: =Colombia!$D$2 -> 45961
A18: 1. Europe | B18: =CzechRepublic!$D$4 -> BU Czech Republic | C18: =CzechRepublic!$D$17 -> Czech Republic | D18: =CzechRepublic!$D$15 -> Prague | E18: =CzechRepublic!$D$16 -> 170 00 | F18: =CzechRepublic!$D$14 -> Jankovcova 1596/14B | G18: =CzechRepublic!$D$18 -> Rental | H18: =CzechRepublic!$D$11 -> CZ01 | I18: =CzechRepublic!$D$19 -> No | J18: =CzechRepublic!$D$13 -> 2nd floor in new constructed bulding | K18: =CzechRepublic!$D$24 -> 1293.19 | L18: =CzechRepublic!$D$26 -> CZK/EUR | M18: =CzechRepublic!$D$28 -> 144 | N18: =CzechRepublic!$D$29 -> indexation only for the price per offices - for 2025 = 2,5% | O18: =CzechRepublic!$D$27 -> 0 | P18: =CzechRepublic!$D$30 -> 90855.8 | Q18: =CzechRepublic!$D$46 -> 171 | R18: =CzechRepublic!$D$50 -> 126 | S18: =R18/Q18 -> 0.73684211 | T18: =K18/R18 -> 10.263413 | U18: =K18/Q18 -> 7.5625146 | V18: =CzechRepublic!$D$33 -> 40210 | W18: =CzechRepublic!$D$40 -> 46599 | X18: =CzechRepublic!$D$34 -> 45900 | Y18: =CzechRepublic!$D$42 -> No | Z18: =CzechRepublic!$D$43 -> No | AA18: =CzechRepublic!$D$44 -> No | AB18: =CzechRepublic!$D$9 -> 0 | AC18: =CzechRepublic!$D$2 -> 45925
A19: 1. Europe | B19: =CzechRepublic!$D$4 -> BU Czech Republic | C19: =CzechRepublic!$D$17 -> Czech Republic | D19: =CzechRepublic!$E$15 -> Bratislava | E19: =CzechRepublic!$E$16 -> 811 05 | F19: =CzechRepublic!$E$14 -> Čajakova 18 | G19: =CzechRepublic!$E$18 -> Rental | H19: =CzechRepublic!$E$11 -> CZ02 | I19: =CzechRepublic!$E$19 -> No | J19: =CzechRepublic!$E$13 -> 2nd floor old bulding, downtown of the city | K19: =CzechRepublic!$E$24 -> 74 | L19: =CzechRepublic!$E$26 -> EUR | M19: =CzechRepublic!$E$28 -> 168 | N19: =CzechRepublic!$E$29 -> no indexation | O19: =CzechRepublic!$E$27 -> 0 | P19: =CzechRepublic!$E$30 -> 50.4 | Q19: =CzechRepublic!$E$46 -> 5 | R19: =CzechRepublic!$E$50 -> 6 | S19: =R19/Q19 -> 1.2 | T19: =K19/R19 -> 12.333333 | U19: =K19/Q19 -> 14.8 | V19: =CzechRepublic!$E$33 -> 37669 | W19: =CzechRepublic!$E$40 -> Indefinite | X19: =CzechRepublic!$E$34 -> 3 months notice at any given time | Y19: =CzechRepublic!$E$42 -> No | Z19: =CzechRepublic!$E$43 -> No | AA19: =CzechRepublic!$E$44 -> No | AB19: =CzechRepublic!$E$9 -> 0 | AC19: =CzechRepublic!$E$2 -> 0
A20: 4. H&L | B20: =Egypt!$D$4 -> Nextcare | C20: =Egypt!$D$17 -> Egypt | D20: =Egypt!$D$15 -> New Cairo | E20: =Egypt!$D$16 -> N/A | F20: =Egypt!$D$14 -> Emerald Twin Plaza, Plot No. (6), 1st settlement, New Cairo, Cairo, Egypt | G20: =Egypt!$D$18 -> Rental | H20: =Egypt!$D$11 -> EG01 | I20: =Egypt!$D$19 -> No | J20: =Egypt!$D$13 -> 2nd floor | K20: =Egypt!$D$24 -> 5380 | L20: =Egypt!$D$26 -> EGP | M20: =Egypt!$D$28 -> 4898.88 | N20: =Egypt!$D$29 -> 8% annual | O20: =Egypt!$D$27 -> 26355974 | P20: =Egypt!$D$30 -> 1554.8204 | Q20: =Egypt!$D$46 -> 1251 | R20: =Egypt!$D$50 -> 769 | S20: =R20/Q20 -> 0.61470823 | T20: =K20/R20 -> 6.9960988 | U20: =K20/Q20 -> 4.3005596 | V20: =Egypt!$D$33 -> 45078 | W20: =Egypt!$D$40 -> 48365 | X20: =Egypt!$D$34 -> 48365 | Y20: =Egypt!$D$42 -> No | Z20: =Egypt!$D$43 -> N/A | AA20: =Egypt!$D$44 -> No | AB20: =Egypt!$D$9 -> Ismail Abdelfatah /Amal Evram | AC20: =Egypt!$D$2 -> 46042
A21: 4. H&L | B21: =Egypt!$D$4 -> Nextcare | C21: =Egypt!$D$17 -> Egypt | D21: =Egypt!$E$15 -> New Cairo | E21: =Egypt!$E$16 -> N/A | F21: =Egypt!$E$14 -> Emerald Twin Plaza, Plot No. (6), 1st settlement, New Cairo, Cairo, Egypt | G21: =Egypt!$E$18 -> Rental | H21: =Egypt!$E$11 -> EG01 | I21: =Egypt!$E$19 -> No | J21: =Egypt!$E$13 -> M1 | K21: =Egypt!$E$24 -> 130 | L21: =Egypt!$E$26 -> EGP | M21: =Egypt!$E$28 -> 9000 | N21: =Egypt!$E$29 -> NA | O21: =Egypt!$E$27 -> 1170000 | P21: =Egypt!$E$30 -> 0 | Q21: =Egypt!$E$46 -> 0 | R21: =Egypt!$E$50 -> 0 | S21: =R21/Q21 -> #DIV/0! | T21: =K21/R21 -> #DIV/0! | U21: =K21/Q21 -> #DIV/0! | V21: =Egypt!$E$33 -> 45261 | W21: =Egypt!$E$40 -> 46356 | X21: =Egypt!$E$34 -> 46356 | Y21: =Egypt!$E$42 -> No | Z21: =Egypt!$E$43 -> NO | AA21: =Egypt!$E$44 -> NO | AB21: =Egypt!$E$9 -> Ismail Abdelfatah /Amal Evram | AC21: =Egypt!$E$2 -> 0
A22: 4. H&L | B22: =Egypt!$D$4 -> Nextcare | C22: =Egypt!$F$17 -> Egypt | D22: =Egypt!$F$15 -> Mokattem city | E22: =Egypt!$F$16 -> N/A | F22: =Egypt!$F$14 -> Street 9, Plot no. 8230, Mokattam city, Cairo | G22: =Egypt!$F$18 -> Rental | H22: =Egypt!$F$11 -> EG02 | I22: =Egypt!$F$19 -> No | J22: =Egypt!$F$13 -> ground floor | K22: =Egypt!$F$24 -> 37.16 | L22: =Egypt!$F$26 -> EGP | M22: =Egypt!$F$28 -> 8073.197 | N22: =Egypt!$F$29 -> 10% Annual | O22: =Egypt!$F$27 -> 300000 | P22: =Egypt!$F$30 -> 0 | Q22: =Egypt!$F$46 -> 0 | R22: =Egypt!$F$50 -> 0 | S22: =R22/Q22 -> #DIV/0! | T22: =K22/R22 -> #DIV/0! | U22: =K22/Q22 -> #DIV/0! | V22: =Egypt!$F$33 -> 44501 | W22: =Egypt!$F$40 -> 46325 | X22: =Egypt!$F$34 -> 46325 | Y22: =Egypt!$F$42 -> NO | Z22: =Egypt!$F$43 -> NO | AA22: =Egypt!$F$44 -> NO | AB22: =Egypt!$F$9 -> Ismail Abdelfatah /Amal Evram | AC22: =Egypt!$F$2 -> 0
A23: 1. Europe | B23: =UK!$F$4 -> BU United Kingdom | C23: =UK!$F$17 -> England | D23: =UK!$F$15 -> London | E23: =UK!$F$16 -> EC2 | F23: =UK!$F$14 -> 15 Bishopsgate, London, EC2 | G23: =UK!$F$18 -> Sublease | H23: =UK!$F$11 -> 0 | I23: =UK!$F$19 -> Y | J23: =UK!$F$13 -> 7 desks - hotdesking for sales and pricing | K23: =UK!$F$24 -> 7 desks | L23: =UK!$F$26 -> Stg | M23: =UK!$F$28 -> 140k approx | N23: =UK!$F$29 -> Advised by Az Mgt Serv annaully | O23: =UK!$F$27 -> 20k per desk p/a. Final figures to be advised | P23: =UK!$F$30 -> Included in cost per desk | Q23: =UK!$F$46 -> 27 currently | R23: =UK!$F$50 -> 0 | S23: =R23/Q23 -> #VALUE! | T23: =K23/R23 -> #VALUE! | U23: =K23/Q23 -> #VALUE! | V23: =UK!$F$33 -> Nov 25 approx | W23: =UK!$F$40 -> 1 year approval | X23: =UK!$F$34 -> We have 1 year rolling approval | Y23: =UK!$F$42 -> Once signed it will be provided | Z23: =UK!$F$43 -> Yes | AA23: =UK!$F$44 -> Unknown | AB23: =UK!$F$9 -> International Health | AC23: =UK!$F$2 -> 0
A24: 1. Europe | B24: =France!$D$4 -> BU France | C24: =France!$G$17 -> France | D24: =France!$G$15 -> Chatillon | E24: =France!$G$16 -> 92320 | F24: =France!$G$14 -> 79-81 Rue Pierre Semard | G24: =France!$G$18 -> Rental | H24: =France!$G$11 -> FR05 | I24: =France!$G$19 -> No | J24: =France!$G$13 -> Ground, 1st and 2nd Floor | K24: =France!$G$24 -> 1269 | L24: =France!$G$26 -> EUR | M24: =France!$G$28 -> 308.12 | N24: =France!$G$29 -> yearly ILAT | O24: =France!$G$27 -> 0 | P24: =France!$G$30 -> 195000 | Q24: =France!$G$46 -> 99 | R24: =France!$G$50 -> 117 | S24: =R24/Q24 -> 1.1818182 | T24: =K24/R24 -> 10.846154 | U24: =K24/Q24 -> 12.818182 | V24: =France!$G$33 -> 43009 | W24: =France!$G$40 -> 46295 | X24: =France!$G$34 -> 46295 | Y24: =France!$G$42 -> No | Z24: =France!$G$43 -> No | AA24: =France!$G$44 -> No | AB24: =France!$G$9 -> 0 | AC24: =France!$G$2 -> 0
A25: 1. Europe | B25: =France!$D$4 -> BU France | C25: =France!$F$17 -> France | D25: =France!$F$15 -> Saint Ouen | E25: =France!$F$16 -> 93400 | F25: =France!$F$14 -> 151 Boulevard Victor Hugo | G25: =France!$F$18 -> Rental | H25: =France!$F$11 -> FR03 | I25: =France!$F$19 -> No | J25: =France!$F$13 -> 3rd floor | K25: =France!$F$24 -> 2127 | L25: =France!$F$26 -> EUR | M25: =France!$F$28 -> 368.4598 | N25: =France!$F$29 -> ILAT | O25: =France!$F$27 -> 0 | P25: =France!$F$30 -> 235.07287 | Q25: =France!$F$46 -> 123 | R25: =France!$F$50 -> 136 | S25: =R25/Q25 -> 1.1056911 | T25: =K25/R25 -> 15.639706 | U25: =K25/Q25 -> 17.292683 | V25: =France!$F$33 -> 45078 | W25: =France!$F$40 -> 46356 | X25: =France!$F$34 -> 46173 | Y25: =France!$F$42 -> Yes | Z25: =France!$F$43 -> Yes | AA25: =France!$F$44 -> HQE exploitation | AB25: =France!$F$9 -> 0 | AC25: =France!$F$2 -> 0
A26: 1. Europe | B26: =France!$D$4 -> BU France | C26: =France!$H$17 -> France | D26: =France!$H$15 -> Armentières | E26: =France!$H$16 -> 59280 | F26: =France!$H$14 -> 85 Quai de Beauvais | G26: =France!$H$18 -> Rental | H26: =France!$H$11 -> FR06 | I26: =France!$H$19 -> No | J26: =France!$H$13 -> Whole Building | K26: =France!$H$24 -> 235 | L26: =France!$H$26 -> EUR | M26: =France!$H$28 -> 129.31 | N26: =France!$H$29 -> yearly ILC | O26: =France!$H$27 -> 0 | P26: =France!$H$30 -> 50000 | Q26: =France!$H$46 -> 13 | R26: =France!$H$50 -> 27 | S26: =R26/Q26 -> 2.0769231 | T26: =K26/R26 -> 8.7037037 | U26: =K26/Q26 -> 18.076923 | V26: =France!$H$33 -> 43739 | W26: =France!$H$40 -> 47026 | X26: =France!$H$34 -> 45930 | Y26: =France!$H$42 -> No | Z26: =France!$H$43 -> No | AA26: =France!$H$44 -> No | AB26: =France!$H$9 -> 0 | AC26: =France!$H$2 -> 0
A27: 1. Europe | B27: =France!$D$4 -> BU France | C27: =France!$D$17 -> France | D27: =France!$E$15 -> Le Mans | E27: =France!$E$16 -> 72000 | F27: =France!$E$14 -> Chemin aux bœuf & les Hunaudières | G27: =France!$E$18 -> Rental | H27: =France!$E$11 -> FR02 | I27: =France!$E$19 -> No | J27: =France!$E$13 -> Group of 2 buildings | K27: =France!$E$24 -> 4403 | L27: =France!$E$26 -> EUR | M27: =France!$E$28 -> 127.46 | N27: =France!$E$29 -> ILAT indice | O27: =France!$E$27 -> 0 | P27: =France!$E$30 -> 78.128549 | Q27: =France!$E$46 -> 602 | R27: =France!$E$50 -> 430 | S27: =R27/Q27 -> 0.71428571 | T27: =K27/R27 -> 10.239535 | U27: =K27/Q27 -> 7.3139535 | V27: =France!$E$33 -> 43891 | W27: =France!$E$40 -> 47177 | X27: =France!$E$34 -> 46082 | Y27: =France!$E$42 -> No | Z27: =France!$E$43 -> NO | AA27: =France!$E$44 -> No | AB27: =France!$E$9 -> 0 | AC27: =France!$E$2 -> 0
A28: 1. Europe | B28: =France!$D$4 -> BU France | C28: =France!$D$17 -> France | D28: =France!$D$15 -> Saint Ouen | E28: =France!$D$16 -> 93400 | F28: =France!$D$14 -> 7 rue Dora Maar | G28: =France!$D$18 -> Rental | H28: =France!$D$11 -> FR01 | I28: =France!$D$19 -> No | J28: =France!$D$13 -> Group of 2 buildings composed of all ground floor part of 1st floor 2nd, 3rd, 4th, 5th,7th floors | K28: =France!$D$24 -> 12407 | L28: =France!$D$26 -> EUR | M28: =France!$D$28 -> 353.15 | N28: =France!$D$29 -> ILAT Indice | O28: =France!$D$27 -> 0 | P28: =France!$D$30 -> 258.64431 | Q28: =France!$D$46 -> 1193 | R28: =France!$D$50 -> 1020 | S28: =R28/Q28 -> 0.85498743 | T28: =K28/R28 -> 12.163725 | U28: =K28/Q28 -> 10.399832 | V28: =France!$D$33 -> 42125 | W28: =France!$D$40 -> 49064 | X28: =France!$D$34 -> 47968 | Y28: =France!$D$42 -> Yes | Z28: =France!$D$43 -> NO | AA28: =France!$D$44 -> No | AB28: =France!$D$9 -> 0 | AC28: =France!$D$2 -> 45979
A29: 1. Europe | B29: =LaReunion!$D$4 -> BU Reunion | C29: =LaReunion!$D$17 -> France | D29: =LaReunion!$D$15 -> Sainte-Marie, La Réserve | E29: =LaReunion!$D$16 -> 97438 | F29: =LaReunion!$D$14 -> 32 rue du Général de Gaulle | G29: =LaReunion!$D$18 -> Rental | H29: =LaReunion!$D$11 -> FR04 | I29: =LaReunion!$D$19 -> No | J29: =LaReunion!$D$13 -> 2nd floor | K29: =LaReunion!$D$24 -> 1100 | L29: =LaReunion!$D$26 -> EUR | M29: =LaReunion!$D$28 -> 11.47 | N29: =LaReunion!$D$29 -> 0.035 | O29: =LaReunion!$D$27 -> 0 | P29: =LaReunion!$D$30 -> 125,39€ m²/year soit 12,54€ m²/month | Q29: =LaReunion!$D$46 -> 286 | R29: =LaReunion!$D$50 -> 292 | S29: =R29/Q29 -> 1.020979 | T29: =K29/R29 -> 3.7671233 | U29: =K29/Q29 -> 3.8461538 | V29: =LaReunion!$D$33 -> 42736 | W29: =LaReunion!$D$40 -> 47118 | X29: =LaReunion!$D$34 -> 46022 | Y29: =LaReunion!$D$42 -> No | Z29: =LaReunion!$D$43 -> No | AA29: =LaReunion!$D$44 -> No | AB29: =LaReunion!$D$9 -> 0 | AC29: =LaReunion!$D$2 -> 45988
A30: 1. Europe | B30: =LaReunion!$F$4 -> BU Reunion | C30: =LaReunion!$F$17 -> France | D30: =LaReunion!$F$15 -> Sainte-Marie, La Réserve | E30: =LaReunion!$F$16 -> 97438 | F30: =LaReunion!$F$14 -> 32 rue du Général de Gaulle | G30: =LaReunion!$F$18 -> Rental | H30: =LaReunion!$F$11 -> FR04 | I30: =LaReunion!$F$19 -> No | J30: =LaReunion!$F$13 -> 1st floor | K30: =LaReunion!$F$24 -> 550 | L30: =LaReunion!$F$26 -> EUR | M30: =LaReunion!$F$28 -> 12.42 | N30: =LaReunion!$F$29 -> 0.035 | O30: =LaReunion!$F$27 -> 0 | P30: =LaReunion!$F$30 -> 0 | Q30: =LaReunion!$F$46 -> 59 | R30: =LaReunion!$F$50 -> 59 | S30: =R30/Q30 -> 1 | T30: =K30/R30 -> 9.3220339 | U30: =K30/Q30 -> 9.3220339 | V30: =LaReunion!$F$33 -> 44986 | W30: =LaReunion!$F$40 -> 48273 | X30: =LaReunion!$F$34 -> 46081 | Y30: =LaReunion!$F$42 -> No | Z30: =LaReunion!$F$43 -> No | AA30: =LaReunion!$F$44 -> No | AB30: =LaReunion!$F$9 -> 0 | AC30: =LaReunion!$F$2 -> 0
A31: 1. Europe | B31: =LaReunion!$E$4 -> BU Reunion | C31: =LaReunion!$E$17 -> France | D31: =LaReunion!$E$15 -> Sainte-Marie, La Réserve | E31: =LaReunion!$E$16 -> 97438 | F31: =LaReunion!$E$14 -> 32 rue du Général de Gaulle | G31: =LaReunion!$E$18 -> Rental | H31: =LaReunion!$E$11 -> FR04 | I31: =LaReunion!$E$19 -> No | J31: =LaReunion!$E$13 -> 2nd floor | K31: =LaReunion!$E$24 -> 326 | L31: =LaReunion!$E$26 -> EUR | M31: =LaReunion!$E$28 -> 12.83 | N31: =LaReunion!$E$29 -> 0.035 | O31: =LaReunion!$E$27 -> 0 | P31: =LaReunion!$E$30 -> 0 | Q31: =LaReunion!$E$46 -> 85 | R31: =LaReunion!$E$50 -> 89 | S31: =R31/Q31 -> 1.0470588 | T31: =K31/R31 -> 3.6629213 | U31: =K31/Q31 -> 3.8352941 | V31: =LaReunion!$E$33 -> 41944 | W31: =LaReunion!$E$40 -> 48518 | X31: =LaReunion!$E$34 -> 48518 | Y31: =LaReunion!$E$42 -> No | Z31: =LaReunion!$E$43 -> No | AA31: =LaReunion!$E$44 -> No | AB31: =LaReunion!$E$9 -> 0 | AC31: =LaReunion!$E$2 -> 0
A32: 1. Europe | B32: =LaReunion!$G$4 -> BU Reunion | C32: =LaReunion!$G$17 -> France | D32: =LaReunion!$G$15 -> Sainte-Marie, La Réserve | E32: =LaReunion!$G$16 -> 97438 | F32: =LaReunion!$G$14 -> 32 rue du Général de Gaulle | G32: =LaReunion!$G$18 -> Rental | H32: =LaReunion!$G$11 -> FR04 | I32: =LaReunion!$G$19 -> No | J32: =LaReunion!$G$13 -> 1st floor | K32: =LaReunion!$G$24 -> 213 | L32: =LaReunion!$G$26 -> EUR | M32: =LaReunion!$G$28 -> 15.14 | N32: =LaReunion!$G$29 -> 0.035 | O32: =LaReunion!$G$27 -> 0 | P32: =LaReunion!$G$30 -> 0 | Q32: =LaReunion!$G$46 -> 42 | R32: =LaReunion!$G$50 -> 42 | S32: =R32/Q32 -> 1 | T32: =K32/R32 -> 5.0714286 | U32: =K32/Q32 -> 5.0714286 | V32: =LaReunion!$G$33 -> 45387 | W32: =LaReunion!$G$40 -> 48673 | X32: =LaReunion!$G$34 -> 48673 | Y32: =LaReunion!$G$42 -> No | Z32: =LaReunion!$G$43 -> No | AA32: =LaReunion!$G$44 -> No | AB32: =LaReunion!$G$9 -> 0 | AC32: =LaReunion!$G$2 -> 0
A33: 1. Europe | B33: =France!$I$4 -> Global Office | C33: =France!$I$17 -> France | D33: =France!$I$15 -> Saint Ouen | E33: =France!$I$16 -> 93400 | F33: =France!$I$14 -> 7rue Dora Maar | G33: =France!$I$18 -> Rental | H33: =France!$I$11 -> FR01 | I33: =France!$I$19 -> No | J33: =France!$I$13 -> 6 & 8th floor | K33: =France!$I$24 -> 5148 | L33: =France!$I$26 -> EUR | M33: =France!$I$28 -> 349.65035 | N33: =France!$I$29 -> 0.03 | O33: =France!$I$27 -> 0 | P33: =France!$I$30 -> 213.67521 | Q33: =France!$I$46 -> 350 | R33: =France!$I$50 -> 298 | S33: =R33/Q33 -> 0.85142857 | T33: =K33/R33 -> 17.275168 | U33: =K33/Q33 -> 14.708571 | V33: =France!$I$33 -> 42491 | W33: =France!$I$40 -> 49064 | X33: =France!$I$34 -> 47968 | Y33: =France!$I$42 -> Yes | Z33: =France!$I$43 -> Yes | AA33: =France!$I$44 -> No | AB33: =France!$I$9 -> 0 | AC33: =France!$I$2 -> 0
A34: 1. Europe | B34: =Germany!$AC$4 -> Allianz Global Benefits | C34: =Germany!$AC$17 -> Germany | D34: =Germany!$AC$15 -> Munich | E34: =Germany!$AC$16 -> 80335 | F34: =Germany!$AC$14 -> Seidlstrasse 24-24a | G34: =Germany!$AC$18 -> Rental | H34: =Germany!$AC$11 -> AGB01 | I34: =Germany!$AC$19 -> Yes | J34: =Germany!$AC$13 -> part of ground floor | K34: =Germany!$AC$24 -> 191.14 | L34: =Germany!$AC$26 -> EUR | M34: =Germany!$AC$28 -> 984 | N34: =Germany!$AC$29 -> N/A | O34: =Germany!$AC$27 -> 188081.76 | P34: =Germany!$AC$30 -> 252 | Q34: =Germany!$AC$46 -> 30 | R34: =Germany!$AC$50 -> 22 | S34: =R34/Q34 -> 0.73333333 | T34: =K34/R34 -> 8.6881818 | U34: =K34/Q34 -> 6.3713333 | V34: =Germany!$AC$33 -> 45261 | W34: =Germany!$AC$40 -> 48913 | X34: =Germany!$AC$34 -> 47087 | Y34: =Germany!$AC$42 -> No | Z34: =Germany!$AC$43 -> Yes | AA34: =Germany!$AC$44 -> No | AB34: =Germany!$AC$9 -> 0 | AC34: =Germany!$AC$2 -> 0
A35: 1. Europe | B35: =Germany!$AD$4 -> Allianz Global Benefits | C35: =Germany!$AD$17 -> Germany | D35: =Germany!$AD$15 -> Stuttgart | E35: =Germany!$AD$16 -> 70182 | F35: =Germany!$AD$14 -> Uhlandstrasse 2 | G35: =Germany!$AD$18 -> Rental | H35: =Germany!$AD$11 -> AGB02 | I35: =Germany!$AD$19 -> Yes | J35: =Germany!$AD$13 -> part of 1st floor | K35: =Germany!$AD$24 -> 360 | L35: =Germany!$AD$26 -> EUR | M35: =Germany!$AD$28 -> 408 | N35: =Germany!$AD$29 -> N/A | O35: =Germany!$AD$27 -> 146880 | P35: =Germany!$AD$30 -> 108 | Q35: =Germany!$AD$46 -> 30 | R35: =Germany!$AD$50 -> 26 | S35: =R35/Q35 -> 0.86666667 | T35: =K35/R35 -> 13.846154 | U35: =K35/Q35 -> 12 | V35: =Germany!$AD$33 -> 43101 | W35: =Germany!$AD$40 -> indefinite | X35: =Germany!$AD$34 -> anytime | Y35: =Germany!$AD$42 -> No | Z35: =Germany!$AD$43 -> Yes | AA35: =Germany!$AD$44 -> No | AB35: =Germany!$AD$9 -> 0 | AC35: =Germany!$AD$2 -> 0
A36: 1. Europe | B36: =Germany!$F$4 -> BU Germany (AHS) | C36: =Germany!$F$17 -> Germany | D36: =Germany!$F$15 -> Berlin | E36: =Germany!$F$16 -> 12489 | F36: =Germany!$F$14 -> Albert-Einstein-Strasse 1a | G36: =Germany!$F$18 -> Rental | H36: =Germany!$F$11 -> DE02 | I36: =Germany!$F$19 -> No | J36: =Germany!$F$13 -> Ground floor, 1st and 2nd floor | K36: =Germany!$F$24 -> 2391.74 | L36: =Germany!$F$26 -> EUR | M36: =Germany!$F$28 -> 21.212118 | N36: =Germany!$F$29 -> 0.05 | O36: =Germany!$F$27 -> 50733.87 | P36: =Germany!$F$30 -> --- | Q36: =Germany!$F$46 -> 0 | R36: =Germany!$F$50 -> 0 | S36: =R36/Q36 -> #DIV/0! | T36: =K36/R36 -> #DIV/0! | U36: =K36/Q36 -> #DIV/0! | V36: =Germany!$F$33 -> 01.05.2019 | W36: =Germany!$F$40 -> 46157 | X36: =Germany!$F$34 -> 46143 | Y36: =Germany!$F$42 -> No | Z36: =Germany!$F$43 -> No | AA36: =Germany!$F$44 -> No | AB36: =Germany!$F$9 -> Daniel Krauss | AC36: =Germany!$F$2 -> 0
A37: 1. Europe | B37: =Germany!$R$4 -> BU Germany (AHS) | C37: =Germany!$R$17 -> Germany | D37: =Germany!$R$15 -> Neustadt | E37: =Germany!$R$16 -> 67433 | F37: =Germany!$R$14 -> Maximilianstr. 5 | G37: =Germany!$R$18 -> Rental | H37: =Germany!$R$11 -> DE07 | I37: =Germany!$R$19 -> No | J37: =Germany!$R$13 -> 1st floor | K37: =Germany!$R$24 -> 349 | L37: =Germany!$R$26 -> EUR | M37: =Germany!$R$28 -> 8.739255 | N37: =Germany!$R$29 -> 0.05 | O37: =Germany!$R$27 -> 3050 | P37: =Germany!$R$30 -> --- | Q37: =Germany!$R$46 -> 0 | R37: =Germany!$R$50 -> 0 | S37: =R37/Q37 -> #DIV/0! | T37: =K37/R37 -> #DIV/0! | U37: =K37/Q37 -> #DIV/0! | V37: =Germany!$R$33 -> 43497 | W37: =Germany!$R$40 -> 47149 | X37: =Germany!$R$34 -> 46418 | Y37: =Germany!$R$42 -> No | Z37: =Germany!$R$43 -> No | AA37: =Germany!$R$44 -> No | AB37: =Germany!$R$9 -> Daniel Krauss | AC37: =Germany!$R$2 -> 0
A38: 1. Europe | B38: =Germany!$M$4 -> BU Germany (AHS) | C38: =Germany!$M$17 -> Germany | D38: =Germany!$M$15 -> Leipzig | E38: =Germany!$M$16 -> 04105 | F38: =Germany!$M$14 -> Springerstrasse 25 | G38: =Germany!$M$18 -> Rental | H38: =Germany!$M$11 -> DE06 | I38: =Germany!$M$19 -> No | J38: =Germany!$M$13 -> 2nd floor | K38: =Germany!$M$24 -> 322.97 | L38: =Germany!$M$26 -> EUR | M38: =Germany!$M$28 -> 9.2499923 | N38: =Germany!$M$29 -> 0.05 | O38: =Germany!$M$27 -> 2987.47 | P38: =Germany!$M$30 -> 2.23 | Q38: =Germany!$M$46 -> 0 | R38: =Germany!$M$50 -> 0 | S38: =R38/Q38 -> #DIV/0! | T38: =K38/R38 -> #DIV/0! | U38: =K38/Q38 -> #DIV/0! | V38: =Germany!$M$33 -> 43070 | W38: =Germany!$M$40 -> 47452 | X38: =Germany!$M$34 -> 46356 | Y38: =Germany!$M$42 -> 0 | Z38: =Germany!$M$43 -> No | AA38: =Germany!$M$44 -> No | AB38: =Germany!$M$9 -> Daniel Krauss | AC38: =Germany!$M$2 -> 0
A39: 1. Europe | B39: =Germany!$J$4 -> BU Germany (AHS) | C39: =Germany!$J$17 -> Germany | D39: =Germany!$J$15 -> Hamburg | E39: =Germany!$J$16 -> 22297 | F39: =Germany!$J$14 -> Kapstadtring 2 | G39: =Germany!$J$18 -> Rental | H39: =Germany!$J$11 -> DE05 | I39: =Germany!$J$19 -> Yes | J39: =Germany!$J$13 -> part of second floor | K39: =Germany!$J$24 -> 144.85 | L39: =Germany!$J$26 -> EUR | M39: =Germany!$J$28 -> 94.868554 | N39: =Germany!$J$29 -> --- | O39: =Germany!$J$27 -> 13741.71 | P39: =Germany!$J$30 -> --- | Q39: =Germany!$J$46 -> 0 | R39: =Germany!$J$50 -> 0 | S39: =R39/Q39 -> #DIV/0! | T39: =K39/R39 -> #DIV/0! | U39: =K39/Q39 -> #DIV/0! | V39: =Germany!$J$33 -> 43101 | W39: =Germany!$J$40 -> undetermined | X39: =Germany!$J$34 -> undetermined | Y39: =Germany!$J$42 -> No | Z39: =Germany!$J$43 -> Yes | AA39: =Germany!$J$44 -> Yes | AB39: =Germany!$J$9 -> Daniel Krauss | AC39: =Germany!$J$2 -> 0
A40: 1. Europe | B40: =Germany!$Y$4 -> BU Germany (AHS) | C40: =Germany!$Y$17 -> Germany | D40: =Germany!$Y$15 -> Stuttgart | E40: =Germany!$Y$16 -> 70565 | F40: =Germany!$Y$14 -> Heßbrühlstraße 2 | G40: =Germany!$Y$18 -> Rental | H40: =Germany!$Y$11 -> DE08 | I40: =Germany!$Y$19 -> Yes | J40: =Germany!$Y$13 -> part of the 4th floor | K40: =Germany!$Y$24 -> 81.16 | L40: =Germany!$Y$26 -> EUR | M40: =Germany!$Y$28 -> 78.65 | N40: =Germany!$Y$29 -> --- | O40: =Germany!$Y$27 -> 6383.234 | P40: =Germany!$Y$30 -> --- | Q40: =Germany!$Y$46 -> 0 | R40: =Germany!$Y$50 -> 0 | S40: =R40/Q40 -> #DIV/0! | T40: =K40/R40 -> #DIV/0! | U40: =K40/Q40 -> #DIV/0! | V40: =Germany!$Y$33 -> 45839 | W40: =Germany!$Y$40 -> undetermined | X40: =Germany!$Y$34 -> undetermined | Y40: =Germany!$Y$42 -> No | Z40: =Germany!$Y$43 -> Yes | AA40: =Germany!$Y$44 -> Yes | AB40: =Germany!$Y$9 -> Daniel Krauss | AC40: =Germany!$Y$2 -> 0
A41: 1. Europe | B41: =Germany!$H$4 -> BU Germany (AHS) | C41: =Germany!$H$17 -> Germany | D41: =Germany!$H$15 -> Düsseldorf | E41: =Germany!$H$16 -> 40472 | F41: =Germany!$H$14 -> Heltorfer Strasse 4 | G41: =Germany!$H$18 -> Rental | H41: =Germany!$H$11 -> DE03 | I41: =Germany!$H$19 -> No | J41: =Germany!$H$13 -> 3rd floor | K41: =Germany!$H$24 -> 480.14 | L41: =Germany!$H$26 -> EUR | M41: =Germany!$H$28 -> 16.27 | N41: =Germany!$H$29 -> 0.05 | O41: =Germany!$H$27 -> 7811.8778 | P41: =Germany!$H$30 -> 3.5 | Q41: =Germany!$H$46 -> 0 | R41: =Germany!$H$50 -> 0 | S41: =R41/Q41 -> #DIV/0! | T41: =K41/R41 -> #DIV/0! | U41: =K41/Q41 -> #DIV/0! | V41: =Germany!$H$33 -> 43466 | W41: =Germany!$H$40 -> undetermined | X41: =Germany!$H$34 -> 46477 | Y41: =Germany!$H$42 -> No | Z41: =Germany!$H$43 -> No | AA41: =Germany!$H$44 -> No | AB41: =Germany!$H$9 -> Daniel Krauss | AC41: =Germany!$H$2 -> 0
...

Sheet Details-->>>

Sheet Australia
C2: Update date
C4: Country/BU | D4: BU Australia
C5: CRE & FM Function | D5: sbishop@allianz-assistance.com.au
C6: Does your BU have multiple locations? (Please choose "Yes" / "No") | E6: No
C7: How many locations does your BU have (Please enter the number of office locations in your BU) | E7: 1
C9: Contact person | D9: sbishop@allianz-assistance.com.au
C10: Location | D10: Location 1 -310 Ann St | E10: Location 1 - 310 Ann St, Sublet 3 floors | F10: Location 3 - xxx | G10: Location 4 - xxx | H10: Location 5 - xxx | I10: Location 6 - xxx | J10: Location 7 - xxx | K10: Location 8 - xxx | L10: Location 9 - xxx | M10: Location 10 - xxx | N10: Location 11 - xxx | O10: Location 12 - xxx | P10: Location 13 - xxx | Q10: Location 14 - xxx | R10: Location 15 - xxx
C11: Location unique ID | D11: AU01 | E11: AU01
D12: 44 | E12: 44
B13: Describe the space: e.g. "Whole Building" or "1st and 2nd Floors" | C13: Unit Description | D13: Levels 12-18 | E13: Levels 12-14
B14: Please provide the postal address | C14: Street Address | D14: 310 Ann St | E14: 310 Ann St
B15: Try to use the greater metro city where possible | C15: Town | D15: Brisbane | E15: Brisbane
B16: Postcode or Zip code | C16: Postcode | D16: 4000 | E16: 4000
B17: Country - NOT business unit | C17: Country | D17: Australia | E17: Australia
B18: Please choose | C18: Rental / owned? | D18: Rental | E18: Rental
B19: Is the office sublet or rented to you by an Allianz entity? | C19: Is the office located at an Allianz Premises? Yes/No | D19: No | E19: No
B20: Does the Allianz entity provide the respective services as security, cleaning, etc.? | C20: Is the office also actively managed by an Allianz entity? Yes/No | D20: No | E20: No
B21: The business name that signed the lease | C21: Tenant Name | D21: AWP Australia Pty Ltd ACN 097227177 | E21: RPM Global Holdings Limited ACN 010672321
B22: The business name that owns the property | C22: Landlord Name | D22: AM 310 Ann Street Investment Pty Ltd ACN 646 669 285 Trustee under instrument No 720672598 | E22: AWP Australia Pty Ltd ACN 097227177
B23: Please type in "sq. Ft." or "m²" | C23: Office size measured in sq. Ft. or m² | D23: m² | E23: m²
B24: Please specify the gross area of the office in sq. Ft. or m² as per lease agreement | C24: Total area gross | D24: 7993 | E24: 3441
B25: The number of parking spaces in the lease and NOT the area in sq. Ft. or m² | C25: Parking Spaces | D25: 0 | E25: 0
B26: 3 digit international currency code for the local currency e.g. EUR, GBP or USD | C26: Currency Code | D26: AUD | E26: AUD
C27: Total rental costs
B28: Total rental costs/ total sq. Ft. Or m²; in case location is owned, pls use reference prices | C28: Price per /m² Rent (in local currency) | D28: 805.4 | E28: $565/ sqm Less incentive of $88.25 / sqm Net rent $476.75
B29: Please specify, by how much the rent increases over which period of time (e.g.7% per year starting 2025) | C29: Indexation of the rent in percent per year | D29: 3.75% per annum on anniversary date | E29: 3.75% per annum on anniversary date
B30: Please do not include the rental cost | C30: Service fee and facility costs (According to Account 783*)1 - price per m² | D30: =619568+111677 -> 731245 | E30: Base building charges recovered from sub tenant of $98,000 per yr plus a proportion of some of the direct vendor costs that relate to the maintenance of the tenancy
C31: Total fee and facility costs
B32: Please specify, by how many % the costs increases over which period of time (e.g.7% per year starting 2025) | C32: Indexation of service fee and/or facility cost in percent per year | D32: 3.75% per yr for rent | E32: 3.75% per yr for rent
B33: What is the start date of the lease? | C33: Lease Start Date | D33: 43497 | E33: 44743
B34: The next fixed break date in the lease | C34: Next Break Date | D34: 47361 | E34: 46568
B35: The date by which notice must have been served | C35: Next Break Notice Expiry | D35: N | E35: N
B36: Can the contract be terminated before the end of the lease? | C36: Does a termination clause exist? Yes/No | D36: No | E36: No
B37: Please specify the exact conditions of the clause (date, notice period, penalty payments etc.) | C37: If yes, please specify the termination clause
B38: Does the lease automatically renew? | C38: Auto Renewing Lease? Yes/No | D38: No | E38: No
B39: How many months notice to prevent auto-renewal? | C39: Auto Renewal Notice Period (Months) | D39: N/A | E39: N/A
B40: The current lease expiry date (leave blank if the lease is open ended) | C40: Lease End Date | D40: 47361 | E40: 46568
B41: Please choose "Yes" / "No"; in case of yes, please specify in the comment field | C41: Does your BU have the contractual possibility to sublet your property? Yes/No | D41: Yes
B42: Please provide the details by using a separate coulmn | C42: If there is a sublet contract in place, please provide the details in a separate column | D42: Yes | E42: subleaser
B43: Please state only yes, if the whole energy consumption of the location is covered by renewable energy | C43: Is the location operated with renewable energy? Yes/No | D43: No
...

Sheet Austria
C2: Update date | D2: 45919
C4: Country/BU | D4: BU Austria | E4: BU Austria
C6: Does your BU have multiple locations? (Please choose "Yes" / "No") | E6: Yes
C7: How many locations does your BU have (Please enter the number of office locations in your BU) | E7: 3 (Bulgaria + Hungary)
C9: Contact Person
C10: Location | D10: Location 1 - Vienna | E10: Location 2 - Vienna - Extend | F10: Location 3 - xxx | G10: Location 4 - xxx | H10: Location 5 - xxx | I10: Location 6 - xxx | J10: Location 7 - xxx | K10: Location 8 - xxx | L10: Location 9 - xxx | M10: Location 10 - xxx | N10: Location 11 - xxx | O10: Location 12 - xxx | P10: Location 13 - xxx | Q10: Location 14 - xxx | R10: Location 15 - xxx
C11: Location unique ID | D11: AT01 | E11: AT01
B13: Describe the space: e.g. "Whole Building" or "1st and 2nd Floors" | C13: Unit Description | D13: 3rd floor | E13: 3rd floor
B14: Please provide the postal address | C14: Street Address | D14: Linzer Strasse 225 | E14: Linzer Strasse 225
B15: Try to use the greater metro city where possible | C15: Town | D15: Vienna | E15: Vienna
B16: Postcode or Zip code | C16: Postcode | D16: 1140 | E16: 1140
B17: Country - NOT business unit | C17: Country | D17: Austria | E17: Austria
B18: Please choose | C18: Rental / owned? | D18: Rental | E18: rental
B19: Is the office sublet or rented to you by an Allianz entity? | C19: Is the office located at an Allianz Premises? Yes/No | D19: Yes | E19: Yes
B20: Does the Allianz entity provide the respective services as security, cleaning, etc.? | C20: Is the office also actively managed by an Allianz entity? Yes/No | D20: Yes | E20: Yes
B21: The business name that signed the lease | C21: Tenant Name | D21: AWP Austria GmbH | E21: AWP Austria GmbH
B22: The business name that owns the property | C22: Landlord Name | D22: Allianz Technology GmbH | E22: Allianz Technology GmbH
C23: m² | D23: m² | E23: m²
B24: Please specify the gross area of the office in sq. Ft. or m² as per lease agreement | C24: Total area gross | D24: 890 | E24: 150.91
B25: The number of parking spaces in the lease and NOT the area in sq. Ft. or m² | C25: Parking Spaces | D25: 20
B26: 3 digit international currency code for the local currency e.g. EUR, GBP or USD | C26: Currency Code | D26: EUR | E26: EUR
B27: Total rental costs | C27: Total rental costs
B28: Total rental costs/ total sq. Ft. Or m²; in case location is owned, pls use reference prices | C28: Price per sq. Ft./m² Rent (in local currency) | D28: 16,80/m²
B29: Please specify, by how much the rent increases over which period of time (e.g.7% per year starting 2025) | C29: Indexation of the rent in percent per year | D29: CPI
B30: Please do not include the rental cost | C30: Service fee and facility costs (According to Account 783*)1 - price per sq. Ft. or m² | D30: =(11.85+2.6)*12 -> 173.4 | E30: included in the rent
C31: Total fee and facility costs
B32: Please specify, by how many % the costs increases over which period of time (e.g.7% per year starting 2025) | C32: Indexation of service fee and/or facility cost in percent per year | D32: CPI
B33: What is the start date of the lease? | C33: Lease Start Date | D33: 45261 | E33: 45962
B34: The next fixed break date in the lease | C34: Next Break Date | D34: 45444
B35: The date by which notice must have been served | C35: Next Break Notice Expiry | D35: 6 months
B36: Can the contract be terminated before the end of the lease? | C36: Does a termination clause exist? Yes/No | D36: Yes
B37: Please specify the exact conditions of the clause (date, notice period, penalty payments etc.) | C37: If yes, please specify the termination clause | D37: if terminated early, outstanding depreciation costs need to be paid
B38: Does the lease automatically renew? | C38: Auto Renewing Lease? Yes/No | D38: No
B39: How many months notice to prevent auto-renewal? | C39: Auto Renewal Notice Period (Months) | D39: N/A
B40: The current lease expiry date (leave blank if the lease is open ended) | C40: Lease End Date | D40: 47635 | E40: 46142
B41: Please choose "Yes" / "No"; in case of yes, please specify in the comment field | C41: Does your BU have the contractual possibility to sublet your property? Yes/No | D41: No
B42: Please provide the details of the sublease agreement in a separate column of the document | C42: If there is a sublease agreement in place, please provide the details in a separate column | D42: No
B43: Please state only yes, if the whole energy consumption of the location is covered by renewable energy | C43: Is the location operated with renewable energy? Yes/No | D43: Yes
B44: It could be an internationally recognized certificate (LEED, BREEAM, Green Star, etc.) or a more locally recognized certificate (e.g. DGNB in Germany) | C44: Does the office building hold any sustainability certificate? Yes/No - If yes please specify | D44: No
C46: Number of HC working in this location as of Sept 2025 | D46: 220
...

Sheet Bahrain
C2: Update date | D2: 26/01/2026
C4: Country/BU | D4: Nextcare | E4: Nextcare
C6: Does your BU have multiple locations? (Please choose "Yes" / "No") | E6: Yes
C7: How many locations does your BU have (Please enter the number of office locations in your BU) | E7: 23
C9: Contact Person | D9: Angelyn Valeza | E9: Angelyn Valeza
C10: Location | D10: Location 21 - Manama | E10: Location 22 - Manama | F10: Location 3 - | G10: Location 4 - | H10: Location 5 - | I10: Location 6 - | J10: Location 7 - | K10: Location 8 - | L10: Location 9 - | M10: Location 10 -
C11: Location unique ID | D11: BH01 | E11: BH01
B13: Describe the space: e.g. "Whole Building" or "1st and 2nd Floors" | C13: Unit Description | D13: 12th floor - office 1501 + 1502 | E13: 12th floor - office 1503 + 1504
B14: Please provide the postal address | C14: Street Address | D14: Exhibition Tower, Building No. 614, Road No. 1011, Block No. 410, Sanabis | E14: Exhibition Tower, Building No. 614, Road No. 1011, Block No. 410, Sanabis
B15: Try to use the greater metro city where possible | C15: Town | D15: Manama | E15: Manama
B16: Postcode or Zip code | C16: Postcode | D16: N/A | E16: N/A
B17: Country - NOT business unit | C17: Country | D17: Kingdom of Bahrain | E17: Kingdom of Bahrain
B18: Please choose | C18: Rental / owned? | D18: Rental | E18: Rental
B19: Is the office sublet or rented to you by an Allianz entity? | C19: Is the office located at an Allianz Premises? Yes/No | D19: No | E19: No
B20: Does the Allianz entity provide the respective services as security, cleaning, etc.? | C20: Is the office also actively managed by an Allianz entity? Yes/No | D20: No | E20: No
B21: The business name that signed the lease | C21: Tenant Name | D21: Nextcare Bahrain Ancillary Services B.S.C. Closed | E21: AWP MEA Holdings Co WLL
B22: The business name that owns the property | C22: Landlord Name | D22: Tylos Building Materials W.L.L. | E22: Tylos Building Materials W.L.L.
B23: Unit sq FT or m² | C23: m² | D23: m² | E23: m²
B24: Please specify the gross area of the office in sq. Ft. or m² as per lease agreement | C24: Total area gross | D24: 275 | E24: 275
B25: The number of parking spaces in the lease and NOT the area in sq. Ft. or m² | C25: Parking Spaces | D25: 3 | E25: 3
B26: 3 digit international currency code for the local currency e.g. EUR, GBP or USD | C26: Currency Code | D26: BHD | E26: BHD
B27: Total rental costs | C27: Total rental costs | D27: 10200 | E27: 10200
B28: Total rental costs/ total sq. Ft. Or m²; in case location is owned, pls use reference prices | C28: Price per sq. Ft./m² Rent (in local currency) | D28: =D27/D24 -> 37.090909 | E28: =E27/E24 -> 37.090909
B29: Please specify, by how much the rent increases over which period of time (e.g.7% per year starting 2025) | C29: Indexation of the rent in percent per year | D29: 6% every two years | E29: 6% every two years
B30: Please do not include the rental cost | C30: Service fee and facility costs (According to Account 783*)1 - price per sq. Ft. or m² | D30: =D31/D24 -> 3.1540727 | E30: =E31/E24 -> 0
C31: Total fee and facility costs | D31: 867.37 | E31: 0
B32: Please specify, by how many % the costs increases over which period of time (e.g.7% per year starting 2025) | C32: Indexation of service fee and/or facility cost in percent per year
B33: What is the start date of the lease? | C33: Lease Start Date | D33: 44713 | E33: 44713
B34: The next fixed break date in the lease | C34: Next Break Date | D34: anytime | E34: anytime
B35: The date by which notice must have been served | C35: Next Break Notice Expiry | D35: N/A | E35: N/A
B36: Can the contract be terminated before the end of the lease? | C36: Does a termination clause exist? Yes/No | D36: Yes | E36: Yes
B37: Please specify the exact conditions of the clause (date, notice period, penalty payments etc.) | C37: If yes, please specify the termination clause | D37: 1 month notice can be given to vacate but after 1 year | E37: 1 month notice can be given to vacate but after 1 year
B38: Does the lease automatically renew? | C38: Auto Renewing Lease? Yes/No | D38: Yes | E38: Yes
B39: How many months notice to prevent auto-renewal? | C39: Auto Renewal Notice Period (Months) | D39: 1 month | E39: 1 month
B40: The current lease expiry date (leave blank if the lease is open ended) | C40: Lease End Date | D40: 46538 | E40: 46538
B41: Please choose "Yes" / "No"; in case of yes, please specify in the comment field | C41: Does your BU have the contractual possibility to sublet your property? Yes/No | D41: No | E41: No
B42: Please provide the details of the sublease agreement in a separate column of the document | C42: If there is a sublease agreement (external or internal) in place, please provide the details in a separate column | D42: No | E42: No
B43: Please state only yes, if the whole energy consumption of the location is covered by renewable energy | C43: Is the location operated with renewable energy? Yes/No | D43: N/A | E43: N/A
B44: It could be an internationally recognized certificate (LEED, BREEAM, Green Star, etc.) or a more locally recognized certificate (e.g. DGNB in Germany) | C44: Does the office building hold any sustainability certificate? Yes/No - If yes please specify | D44: No | E44: No
C46: Number of HC working in this location | D46: 23 | E46: 0
...

Sheet Belgium
C2: Update date | D2: 46070
C4: Country/BU | D4: International Health
C6: Does your BU have multiple locations? (Please choose "Yes" / "No") | E6: No
C7: How many locations does your BU have (Please enter the number of office locations in your BU) | E7: 1
C9: Contact Person
C10: Location | D10: Location 1 - Brussels Office | E10: Location 2 - | F10: Location 3 - | G10: Location 4 - | H10: Location 5 - | I10: Location 6 - | J10: Location 7 - | K10: Location 8 - | L10: Location 9 - | M10: Location 10 -
C11: Location unique ID | D11: BE01
B13: Describe the space: e.g. "Whole Building" or "1st and 2nd Floors" | C13: Unit Description | D13: 4th floor & 50% of the 5th floor
B14: Please provide the postal address | C14: Street Address | D14: Allianz Tower Koning Boulevard du Roi Albert II, 32 (Albert II Laan)
B15: Try to use the greater metro city where possible | C15: Town | D15: Brussels
B16: Postcode or Zip code | C16: Postcode | D16: 1000
B17: Country - NOT business unit | C17: Country | D17: Belgium
B18: Please choose | C18: Rental / owned? | D18: Rental
B19: Is the office sublet or rented to you by an Allianz entity? | C19: Is the office located at an Allianz Premises? Yes/No | D19: Yes
B20: Does the Allianz entity provide the respective services as security, cleaning, etc.? | C20: Is the office also actively managed by an Allianz entity? Yes/No | D20: Yes
B21: The business name that signed the lease | C21: Tenant Name | D21: AWP P&C SA - Belgian Branch
B22: The business name that owns the property | C22: Landlord Name | D22: AZ Benelux
B23: Unit sq FT or m² | C23: m² | D23: m²
B24: Please specify the gross area of the office in sq. Ft. or m² as per lease agreement | C24: Total area gross | D24: 1658
B25: The number of parking spaces in the lease and NOT the area in sq. Ft. or m² | C25: Parking Spaces | D25: 12
B26: 3 digit international currency code for the local currency e.g. EUR, GBP or USD | C26: Currency Code | D26: EUR
B27: Total rental costs | C27: Total rental costs | D27: =D28*D24 -> 618434
B28: Total rental costs/ total sq. Ft. Or m²; in case location is owned, pls use reference prices | C28: Price per sq. Ft./m² Rent (in local currency) | D28: 373
B29: Please specify, by how much the rent increases over which period of time (e.g.7% per year starting 2025) | C29: Indexation of the rent in percent per year | D29: app. 3%
B30: Please do not include the rental cost | C30: Service fee and facility costs (According to Account 783*)1 - price per sq. Ft. or m² | D30: 259
C31: Total fee and facility costs | D31: =D30*D24 -> 429422
B32: Please specify, by how many % the costs increases over which period of time (e.g.7% per year starting 2025) | C32: Indexation of service fee and/or facility cost in percent per year | D32: app. 3%
B33: What is the start date of the lease? | C33: Lease Start Date | D33: 43922
B34: The next fixed break date in the lease | C34: Next Break Date | D34: 47208
B35: The date by which notice must have been served | C35: Next Break Notice Expiry | D35: 47208
B36: Can the contract be terminated before the end of the lease? | C36: Does a termination clause exist? Yes/No | D36: NO
B37: Please specify the exact conditions of the clause (date, notice period, penalty payments etc.) | C37: If yes, please specify the termination clause
B38: Does the lease automatically renew? | C38: Auto Renewing Lease? Yes/No | D38: No
B39: How many months notice to prevent auto-renewal? | C39: Auto Renewal Notice Period (Months) | D39: N/A
B40: The current lease expiry date (leave blank if the lease is open ended) | C40: Lease End Date | D40: 47208
B41: Please choose "Yes" / "No"; in case of yes, please specify in the comment field | C41: Does your BU have the contractual possibility to sublet your property? Yes/No | D41: NO
B42: Please provide the details of the sublease agreement in a separate column of the document | C42: If there is a sublease agreement (external or internal) in place, please provide the details in a separate column | D42: No
B43: Please state only yes, if the whole energy consumption of the location is covered by renewable energy | C43: Is the location operated with renewable energy? Yes/No | D43: Yes
B44: It could be an internationally recognized certificate (LEED, BREEAM, Green Star, etc.) or a more locally recognized certificate (e.g. DGNB in Germany) | C44: Does the office building hold any sustainability certificate? Yes/No - If yes please specify | D44: Unknown
C46: Number of HC working in this location | D46: 222
...

Sheet Bulgaria
C2: Update date | D2: 45919
C4: Country/BU | D4: BU Austria
C6: Does your BU have multiple locations? (Please choose "Yes" / "No") | E6: Yes
C7: How many locations does your BU have (Please enter the number of office locations in your BU) | E7: 3
C9: Contact Person
C10: Location | D10: Location 1 - Sofia | E10: Location 2 - xxx | F10: Location 3 - xxx | G10: Location 4 - xxx | H10: Location 5 - xxx | I10: Location 6 - xxx | J10: Location 7 - xxx | K10: Location 8 - xxx | L10: Location 9 - xxx | M10: Location 10 - xxx | N10: Location 11 - xxx | O10: Location 12 - xxx | P10: Location 13 - xxx | Q10: Location 14 - xxx | R10: Location 15 - xxx
C11: Location unique ID | D11: BU01
B13: Describe the space: e.g. "Whole Building" or "1st and 2nd Floors" | C13: Unit Description | D13: part of a floor
B14: Please provide the postal address | C14: Street Address | D14: 16 Srebarna Str.
B15: Try to use the greater metro city where possible | C15: Town | D15: Sofia
B16: Postcode or Zip code | C16: Postcode | D16: 1407
B17: Country - NOT business unit | C17: Country | D17: Bulgaria
